Workbook

Sheet 實驗數據
G2: 第一次實驗 | P2: 第二次實驗
G3: A：實驗數據 | P3: A：實驗數據
G4: 光具座與固定架 距離L (mm) | I4: 單狹縫寬度a (mm) | K4: 雙狹縫相距d (mm) | M4: 雷射二極體組 波長λ (mm) | P4: 光具座與固定架 距離L (mm) | R4: 單狹縫寬度a (mm) | T4: 雙狹縫相距d (mm) | V4: 雷射二極體組 波長λ (mm)
G6: 500 | I6: 0.05 | K6: 0.25 | M6: 0.000635 | P6: 500 | R6: 0.05 | T6: 0.25 | V6: 0.000635
G7: 位置(mm) | H7: 照度 | I7: 位置(mm) | J7: 照度 | K7: 位置(mm) | L7: 照度 | M7: 位置(mm) | N7: 照度 | P7: 位置(mm) | Q7: 照度 | R7: 位置(mm) | S7: 照度 | T7: 位置(mm) | U7: 照度 | V7: 位置(mm) | W7: 照度
G8: -20 | H8: 0.788 | I8: -10 | J8: 1.832 | K8: 0 | L8: 130.46 | M8: 10 | N8: 3.632 | P8: -20 | Q8: 0.672 | R8: -10 | S8: 1.348 | T8: 0 | U8: 129.6 | V8: 10 | W8: 4.015
G9: =G8 + 0.2 -> -19.8 | H9: 0.721 | I9: =I8 + 0.2 -> -9.8 | J9: 0.668 | K9: =K8 + 0.2 -> 0.2 | L9: 34.17 | M9: =M8 + 0.2 -> 10.2 | N9: 2.405 | P9: =P8 + 0.2 -> -19.8 | Q9: 0.611 | R9: =R8 + 0.2 -> -9.8 | S9: 0.538 | T9: =T8 + 0.2 -> 0.2 | U9: 45.11 | V9: =V8 + 0.2 -> 10.2 | W9: 2.871
G10: =G9 + 0.2 -> -19.6 | H10: 0.232 | I10: =I9 + 0.2 -> -9.6 | J10: 1.059 | K10: =K9 + 0.2 -> 0.4 | L10: 9.98 | M10: =M9 + 0.2 -> 10.4 | N10: 1.445 | P10: =P9 + 0.2 -> -19.6 | Q10: 0.348 | R10: =R9 + 0.2 -> -9.6 | S10: 0.851 | T10: =T9 + 0.2 -> 0.4 | U10: 9.88 | V10: =V9 + 0.2 -> 10.4 | W10: 1.7
G11: =G10 + 0.2 -> -19.4 | H11: 0.116 | I11: =I10 + 0.2 -> -9.4 | J11: 3.115 | K11: =K10 + 0.2 -> 0.6 | L11: 22.82 | M11: =M10 + 0.2 -> 10.6 | N11: 1.35 | P11: =P10 + 0.2 -> -19.4 | Q11: 0.155 | R11: =R10 + 0.2 -> -9.4 | S11: 2.26 | T11: =T10 + 0.2 -> 0.6 | U11: 40.32 | V11: =V10 + 0.2 -> 10.6 | W11: 1.337
G12: =G11 + 0.2 -> -19.2 | H12: 0.342 | I12: =I11 + 0.2 -> -9.2 | J12: 4.903 | K12: =K11 + 0.2 -> 0.8 | L12: 78.26 | M12: =M11 + 0.2 -> 10.8 | N12: 1.529 | P12: =P11 + 0.2 -> -19.2 | Q12: 0.216 | R12: =R11 + 0.2 -> -9.2 | S12: 4.81 | T12: =T11 + 0.2 -> 0.8 | U12: 97.1 | V12: =V11 + 0.2 -> 10.8 | W12: 1.55
G13: =G12 + 0.2 -> -19 | H13: 0.581 | I13: =I12 + 0.2 -> -9 | J13: 5.057 | K13: =K12 + 0.2 -> 1 | L13: 129.81 | M13: =M12 + 0.2 -> 11 | N13: 1.524 | P13: =P12 + 0.2 -> -19 | Q13: 0.499 | R13: =R12 + 0.2 -> -9 | S13: 4.939 | T13: =T12 + 0.2 -> 1 | U13: 142.58 | V13: =V12 + 0.2 -> 11 | W13: 1.224
G14: =G13 + 0.2 -> -18.8 | H14: 0.983 | I14: =I13 + 0.2 -> -8.8 | J14: 3.306 | K14: =K13 + 0.2 -> 1.2 | L14: 134.06 | M14: =M13 + 0.2 -> 11.2 | N14: 0.935 | P14: =P13 + 0.2 -> -18.8 | Q14: 0.829 | R14: =R13 + 0.2 -> -8.8 | S14: 2.91 | T14: =T13 + 0.2 -> 1.2 | U14: 125.29 | V14: =V13 + 0.2 -> 11.2 | W14: 0.689
G15: =G14 + 0.2 -> -18.6 | H15: 0.964 | I15: =I14 + 0.2 -> -8.6 | J15: 0.915 | K15: =K14 + 0.2 -> 1.4 | L15: 79.91 | M15: =M14 + 0.2 -> 11.4 | N15: 0.668 | P15: =P14 + 0.2 -> -18.6 | Q15: 0.927 | R15: =R14 + 0.2 -> -8.6 | S15: 0.762 | T15: =T14 + 0.2 -> 1.4 | U15: 85.88 | V15: =V14 + 0.2 -> 11.4 | W15: 0.753
G16: =G15 + 0.2 -> -18.4 | H16: 0.477 | I16: =I15 + 0.2 -> -8.4 | J16: 0.637 | K16: =K15 + 0.2 -> 1.6 | L16: 17.44 | M16: =M15 + 0.2 -> 11.6 | N16: 0.878 | P16: =P15 + 0.2 -> -18.4 | Q16: 0.596 | R16: =R15 + 0.2 -> -8.4 | S16: 0.609 | T16: =T15 + 0.2 -> 1.6 | U16: 20.74 | V16: =V15 + 0.2 -> 11.6 | W16: 1.132
G17: =G16 + 0.2 -> -18.2 | H17: 0.25 | I17: =I16 + 0.2 -> -8.2 | J17: 2.198 | K17: =K16 + 0.2 -> 1.8 | L17: 11.79 | M17: =M16 + 0.2 -> 11.8 | N17: 1.329 | P17: =P16 + 0.2 -> -18.2 | Q17: 0.326 | R17: =R16 + 0.2 -> -8.2 | S17: 2.476 | T17: =T16 + 0.2 -> 1.8 | U17: 10.9 | V17: =V16 + 0.2 -> 11.8 | W17: 1.415
G18: =G17 + 0.2 -> -18 | H18: 0.261 | I18: =I17 + 0.2 -> -8 | J18: 4.353 | K18: =K17 + 0.2 -> 2 | L18: 66.32 | M18: =M17 + 0.2 -> 12 | N18: 1.403 | P18: =P17 + 0.2 -> -18 | Q18: 0.214 | R18: =R17 + 0.2 -> -8 | S18: 4.765 | T18: =T17 + 0.2 -> 2 | U18: 56.74 | V18: =V17 + 0.2 -> 12 | W18: 1.183
G19: =G18 + 0.2 -> -17.8 | H19: 0.555 | I19: =I18 + 0.2 -> -7.8 | J19: 4.953 | K19: =K18 + 0.2 -> 2.2 | L19: 100.76 | M19: =M18 + 0.2 -> 12.2 | N19: 0.76 | P19: =P18 + 0.2 -> -17.8 | Q19: 0.46 | R19: =R18 + 0.2 -> -7.8 | S19: 5.11 | T19: =T18 + 0.2 -> 2.2 | U19: 94.48 | V19: =V18 + 0.2 -> 12.2 | W19: 0.767
G20: =G19 + 0.2 -> -17.6 | H20: 0.818 | I20: =I19 + 0.2 -> -7.6 | J20: 2.965 | K20: =K19 + 0.2 -> 2.4 | L20: 96.45 | M20: =M19 + 0.2 -> 12.4 | N20: 0.3113 | P20: =P19 + 0.2 -> -17.6 | Q20: 0.725 | R20: =R19 + 0.2 -> -7.6 | S20: 3.449 | T20: =T19 + 0.2 -> 2.4 | U20: 101.82 | V20: =V19 + 0.2 -> 12.4 | W20: 0.286
... G56: =G55 + 0.2 -> -10.4 | H56: 2.808 | I56: =I55 + 0.2 -> -0.4 | J56: 131.59 | K56: =K55 + 0.2 -> 9.6 | L56: 2.242 | M56: =M55 + 0.2 -> 19.6 | N56: 0.4836 | P56: =P55 + 0.2 -> -10.4 | Q56: 2.586 | R56: =R55 + 0.2 -> -0.4 | S56: 127.1 | T56: =T55 + 0.2 -> 9.6 | U56: 2.254 | V56: =V55 + 0.2 -> 19.6 | W56: 0.46
G57: =G56 + 0.2 -> -10.2 | H57: 2.909 | I57: =I56 + 0.2 -> -0.2 | J57: 155.29 | K57: =K56 + 0.2 -> 9.8 | L57: 3.623 | M57: =M56 + 0.2 -> 19.8 | N57: 0.2491 | P57: =P56 + 0.2 -> -10.2 | Q57: 2.252 | R57: =R56 + 0.2 -> -0.2 | S57: 155.04 | T57: =T56 + 0.2 -> 9.8 | U57: 3.561 | V57: 19.8 | W57: 0.2382
M58: =M57 + 0.2 -> 20 | N58: 0.1144 | V58: =V57 + 0.2 -> 20 | W58: 0.1026
E96: B：尋找X1、Xr | N96: B：尋找X1、Xr
F97: 第一亮紋 | G97: 第二亮紋 | H97: 第三亮紋 | I97: 第四亮紋 | J97: 第五亮紋 | K97: 第一暗紋 | O97: 第一亮紋 | P97: 第二亮紋 | Q97: 第三亮紋 | R97: 第四亮紋 | S97: 第五亮紋 | T97: 第一暗紋
E98: Xl (mm) | F98: -1.2 | G98: -2.6 | H98: -3.6 | I98: -5 | K98: -5.8 | N98: Xl (mm) | O98: -1.2 | P98: -2.4 | Q98: -3.6 | R98: -4.2 | T98: -4.6
E99: Xr (mm) | F99: 1.4 | G99: 2.4 | H99: 3.8 | I99: 5 | K99: 5.6 | N99: Xr (mm) | O99: 1.2 | P99: 2.6 | Q99: 3.8 | R99: 4.8 | T99: 5.6
E100: Θ | F100: =ABS((F98-F99)/2/G6) -> 0.0026 | G100: =ABS((G98-G99)/2/G6) -> 0.005 | H100: =ABS((H98-H99)/2/G6) -> 0.0074 | I100: =ABS((I98-I99)/2/G6) -> 0.01 | J100: =ABS((J98-J99)/2/G6) -> 0 | K100: =ABS((K98-K99)/2/G6) -> 0.0114 | N100: Θ | O100: =ABS((O98-O99)/2/P6) -> 0.0024 | P100: =ABS((P98-P99)/2/P6) -> 0.005 | Q100: =ABS((Q98-Q99)/2/P6) -> 0.0074 | R100: =ABS((R98-R99)/2/P6) -> 0.009 | S100: =ABS((S98-S99)/2/P6) -> 0 | T100: =ABS((T98-T99)/2/P6) -> 0.0102
E102: B：尋找X1、Xr(理論值) | N102: B：尋找X1、Xr(理論值)
F103: 第一亮紋 | G103: 第二亮紋 | H103: 第三亮紋 | I103: 第四亮紋 | J103: 第五亮紋 | K103: 第一暗紋 | O103: 第一亮紋 | P103: 第二亮紋 | Q103: 第三亮紋 | R103: 第四亮紋 | S103: 第五亮紋 | T103: 第一暗紋
E104: Xl (mm) | F104: =G6*M6/K6*-1 -> -1.27 | G104: =G6*M6*2/K6*-1 -> -2.54 | H104: =G6*M6*3/K6*-1 -> -3.81 | I104: =G6*M6*4/K6*-1 -> -5.08 | J104: =G6*M6*5/K6*-1 -> -6.35 | K104: =G6*M6/I6*-1 -> -6.35 | N104: Xl (mm) | O104: =P6*V6/T6*-1 -> -1.27 | P104: =P6*V6*2/T6*-1 -> -2.54 | Q104: =P6*V6*3/T6*-1 -> -3.81 | R104: =P6*V6*4/T6*-1 -> -5.08 | S104: =P6*V6*5/T6*-1 -> -6.35 | T104: =P6*V6/R6*-1 -> -6.35
E105: Xr (mm) | F105: =G6*M6/K6 -> 1.27 | G105: =G6*M6*2/K6 -> 2.54 | H105: =G6*M6*3/K6 -> 3.81 | I105: =G6*M6*4/K6 -> 5.08 | J105: =G6*M6*5/K6 -> 6.35 | K105: =G6*M6/I6 -> 6.35 | N105: Xr (mm) | O105: =P6*V6/T6 -> 1.27 | P105: =P6*V6*2/T6 -> 2.54 | Q105: =P6*V6*3/T6*-1 -> -3.81 | R105: =P6*V6*4/T6 -> 5.08 | S105: =P6*V6*5/T6 -> 6.35 | T105: =P6*V6/R6 -> 6.35
E106: Θ | F106: =ABS((F104-F105)/2/G6) -> 0.00254 | G106: =ABS((G104-G105)/2/G6) -> 0.00508 | H106: =ABS((H104-H105)/2/G6) -> 0.00762 | I106: =ABS((I104-I105)/2/G6) -> 0.01016 | J106: =ABS((J104-J105)/2/G6) -> 0.0127 | K106: =ABS((K104-K105)/2/G6) -> 0.0127 | N106: Θ | O106: =ABS((O104-O105)/2/P6) -> 0.00254 | P106: =ABS((P104-P105)/2/P6) -> 0.00508 | Q106: =ABS((Q104-Q105)/2/P6) -> 0 | R106: =ABS((R104-R105)/2/P6) -> 0.01016 | S106: =ABS((S104-S105)/2/P6) -> 0.0127 | T106: =ABS((T104-T105)/2/P6) -> 0.0127
E108: C：計算出單狹縫寬度a及雙狹縫距離d之值 | N108: C：計算出單狹縫寬度a及雙狹縫距離d之值
H109: 理論值 | I109: 實驗值 | J109: 百分誤差 (%) | Q109: 理論值 | R109: 實驗值 | S109: 百分誤差 (%)
E110: 單狹縫寬度a (mm) | G110: Xl | H110: =I6 -> 0.05 | I110: =ABS($G6*$M6/K98) -> 0.054741379 | J110: =ABS((I110-$H110)/$H110*100) -> 9.4827586 | N110: 單狹縫寬度a (mm) | P110: Xl | Q110: =R6 -> 0.05 | R110: =ABS($G6*$M6/T98) -> 0.069021739 | S110: =ABS((R110-$H110)/$H110*100) -> 38.043478
G111: Xr | I111: =ABS(G6*M6/K99) -> 0.056696429 | J111: =ABS((I111-H110)/H110*100) -> 13.392857 | P111: Xr | R111: =ABS(P6*V6/T99) -> 0.056696429 | S111: =ABS((R111-Q110)/Q110*100) -> 13.392857
G112: 平均 | I112: =AVERAGE(I110:I111) -> 0.055718904 | J112: =ABS((I112-H110)/H110*100) -> 11.437808 | P112: 平均 | R112: =AVERAGE(R110:R111) -> 0.062859084 | S112: =ABS((R112-Q110)/Q110*100) -> 25.718168
E113: 雙狹縫距離d (mm) | G113: Xl | H113: =K6 -> 0.25 | I113: =1*M6/F100 -> 0.24423077 | J113: =ABS((I113-H113)/H113*100) -> 2.3076923 | N113: 雙狹縫距離d (mm) | P113: Xl | Q113: =T6 -> 0.25 | R113: =ABS(P6*V6/O98) -> 0.26458333 | S113: =ABS((R113-Q113)/Q113*100) -> 5.8333333
G114: Xr | I114: =2*M6/G100 -> 0.254 | J114: =ABS((I114-H113)/H113*100) -> 1.6 | P114: Xr | R114: =ABS(P6*V6/O99) -> 0.26458333 | S114: =ABS((R114-Q113)/Q113*100) -> 5.8333333
G115: 平均 | I115: =AVERAGE(I113:I114) -> 0.24911538 | J115: =ABS((I115-H113)/H113*100) -> 0.35384615 | P115: 平均 | R115: =AVERAGE(R113:R114) -> 0.26458333 | S115: =ABS((R115-Q113)/Q113*100) -> 5.8333333
E117: D：計算亮紋強度的比例 | N117: D：計算亮紋強度的比例
...

Sheet 計算用
B1: 第一次實驗 | L1: 第二次實驗
E2: 實驗值 | O2: 實驗值
B3: 理論值 | D3: =實驗數據!K6 -> 0.25 | E3: 第一亮紋 | F3: 第二亮紋 | G3: 第四亮紋 | H3: 第五亮紋 | I3: 平均值 | J3: 平均值 | L3: 理論值 | N3: =實驗數據!U6 -> 0 | O3: 第一亮紋 | P3: 第二亮紋 | Q3: 第四亮紋 | R3: 第五亮紋 | S3: 平均值 | T3: 平均值
B4: 雙狹縫距離d (mm) | D4: Xl | E4: =ABS(實驗數據!$G6*實驗數據!$M6/實驗數據!F98) -> 0.26458333 | F4: =ABS(實驗數據!$G6*實驗數據!$M6*2/實驗數據!G98) -> 0.24423077 | G4: =ABS(實驗數據!$G6*實驗數據!$M6*4/實驗數據!I98) -> 0.254 | H4: =ABS(實驗數據!$G6*實驗數據!$M6*5/實驗數據!J98) -> #DIV/0! | I4: =AVERAGE(E4:H4) -> #DIV/0! | J4: =AVERAGE(I4,I6) -> #DIV/0! | L4: 雙狹縫距離d (mm) | N4: Xl | O4: =ABS(實驗數據!$G6*實驗數據!$M6/實驗數據!P98) -> 0.13229167 | P4: =ABS(實驗數據!$G6*實驗數據!$M6*2/實驗數據!R98) -> 0.15119048 | Q4: =ABS(實驗數據!$G6*實驗數據!$M6*4/實驗數據!S98) -> #DIV/0! | R4: =ABS(實驗數據!$G6*實驗數據!$M6*5/實驗數據!T98) -> 0.3451087 | S4: =AVERAGE(O4:R4) -> #DIV/0! | T4: =AVERAGE(S4,S6) -> #DIV/0!
D5: 誤差(%) | E5: =ABS((E4-$D3)/$D3*100) -> 5.8333333 | F5: =ABS((F4-$D3)/$D3*100) -> 2.3076923 | G5: =ABS((G4-$D3)/$D3*100) -> 1.6 | H5: =ABS((H4-$D3)/$D3*100) -> #DIV/0! | I5: =ABS((I4-$D3)/$D3*100) -> #DIV/0! | N5: 誤差(%) | O5: =ABS((O4-$D3)/$D3*100) -> 47.083333 | P5: =ABS((P4-$D3)/$D3*100) -> 39.52381 | Q5: =ABS((Q4-$D3)/$D3*100) -> #DIV/0! | R5: =ABS((R4-$D3)/$D3*100) -> 38.043478 | S5: =ABS((S4-$D3)/$D3*100) -> #DIV/0!
D6: Xr | E6: =ABS(實驗數據!$G6*實驗數據!$M6/實驗數據!F99) -> 0.22678571 | F6: =ABS(實驗數據!$G6*實驗數據!$M6*2/實驗數據!G99) -> 0.26458333 | G6: =ABS(實驗數據!$G6*實驗數據!$M6*4/實驗數據!I99) -> 0.254 | H6: =ABS(實驗數據!$G6*實驗數據!$M6*5/實驗數據!J99) -> #DIV/0! | I6: =AVERAGE(E6:H6) -> #DIV/0! | N6: Xr | O6: =ABS(實驗數據!$G6*實驗數據!$M6/實驗數據!P99) -> 0.12211538 | P6: =ABS(實驗數據!$G6*實驗數據!$M6*2/實驗數據!R99) -> 0.13229167 | Q6: =ABS(實驗數據!$G6*實驗數據!$M6*4/實驗數據!S99) -> #DIV/0! | R6: =ABS(實驗數據!$G6*實驗數據!$M6*5/實驗數據!T99) -> 0.28348214 | S6: =AVERAGE(O6:R6) -> #DIV/0!
D7: 誤差(%) | E7: =ABS((E6-$D3)/$D3*100) -> 9.2857143 | F7: =ABS((F6-$D3)/$D3*100) -> 5.8333333 | G7: =ABS((G6-$D3)/$D3*100) -> 1.6 | H7: =ABS((H6-$D3)/$D3*100) -> #DIV/0! | I7: =ABS((I6-$D3)/$D3*100) -> #DIV/0! | J7: =ABS((J4-$D3)/$D3*100) -> #DIV/0! | N7: 誤差(%) | O7: =ABS((O6-$D3)/$D3*100) -> 51.153846 | P7: =ABS((P6-$D3)/$D3*100) -> 47.083333 | Q7: =ABS((Q6-$D3)/$D3*100) -> #DIV/0! | R7: =ABS((R6-$D3)/$D3*100) -> 13.392857 | S7: =ABS((S6-$D3)/$D3*100) -> #DIV/0! | T7: =ABS((T4-$D3)/$D3*100) -> #DIV/0!
