Workbook

Sheet 實驗數據
G2: 第一次實驗 | P2: 第二次實驗
G3: A：實驗數據 | P3: A：實驗數據
G4: 光具座與固定架 距離L (mm) | I4: 單狹縫寬度a (mm) | K4: 雙狹縫相距d (mm) | M4: 雷射二極體組 波長λ (mm) | P4: 光具座與固定架 距離L (mm) | R4: 單狹縫寬度a (mm) | T4: 雙狹縫相距d (mm) | V4: 雷射二極體組 波長λ (mm)
G6: 500 | M6: 0.000635 | P6: 500 | V6: 0.000635
G7: 位置(mm) | H7: 電壓(mV) | I7: 位置(mm) | J7: 電壓(mV) | K7: 位置(mm) | L7: 電壓(mV) | M7: 位置(mm) | N7: 電壓(mV) | P7: 位置(mm) | Q7: 電壓(mV) | R7: 位置(mm) | S7: 電壓(mV) | T7: 位置(mm) | U7: 電壓(mV) | V7: 位置(mm) | W7: 電壓(mV)
G8: -20 | I8: -10 | K8: 0 | M8: 10 | P8: -20 | R8: -10 | T8: 0 | V8: 10
G9: =G8 + 0.2 -> -19.8 | I9: =I8 + 0.2 -> -9.8 | K9: =K8 + 0.2 -> 0.2 | M9: =M8 + 0.2 -> 10.2 | P9: =P8 + 0.2 -> -19.8 | R9: =R8 + 0.2 -> -9.8 | T9: =T8 + 0.2 -> 0.2 | V9: =V8 + 0.2 -> 10.2
G10: =G9 + 0.2 -> -19.6 | I10: =I9 + 0.2 -> -9.6 | K10: =K9 + 0.2 -> 0.4 | M10: =M9 + 0.2 -> 10.4 | P10: =P9 + 0.2 -> -19.6 | R10: =R9 + 0.2 -> -9.6 | T10: =T9 + 0.2 -> 0.4 | V10: =V9 + 0.2 -> 10.4
G11: =G10 + 0.2 -> -19.4 | I11: =I10 + 0.2 -> -9.4 | K11: =K10 + 0.2 -> 0.6 | M11: =M10 + 0.2 -> 10.6 | P11: =P10 + 0.2 -> -19.4 | R11: =R10 + 0.2 -> -9.4 | T11: =T10 + 0.2 -> 0.6 | V11: =V10 + 0.2 -> 10.6
G12: =G11 + 0.2 -> -19.2 | I12: =I11 + 0.2 -> -9.2 | K12: =K11 + 0.2 -> 0.8 | M12: =M11 + 0.2 -> 10.8 | P12: =P11 + 0.2 -> -19.2 | R12: =R11 + 0.2 -> -9.2 | T12: =T11 + 0.2 -> 0.8 | V12: =V11 + 0.2 -> 10.8
G13: =G12 + 0.2 -> -19 | I13: =I12 + 0.2 -> -9 | K13: =K12 + 0.2 -> 1 | M13: =M12 + 0.2 -> 11 | P13: =P12 + 0.2 -> -19 | R13: =R12 + 0.2 -> -9 | T13: =T12 + 0.2 -> 1 | V13: =V12 + 0.2 -> 11
G14: =G13 + 0.2 -> -18.8 | I14: =I13 + 0.2 -> -8.8 | K14: =K13 + 0.2 -> 1.2 | M14: =M13 + 0.2 -> 11.2 | P14: =P13 + 0.2 -> -18.8 | R14: =R13 + 0.2 -> -8.8 | T14: =T13 + 0.2 -> 1.2 | V14: =V13 + 0.2 -> 11.2
G15: =G14 + 0.2 -> -18.6 | I15: =I14 + 0.2 -> -8.6 | K15: =K14 + 0.2 -> 1.4 | M15: =M14 + 0.2 -> 11.4 | P15: =P14 + 0.2 -> -18.6 | R15: =R14 + 0.2 -> -8.6 | T15: =T14 + 0.2 -> 1.4 | V15: =V14 + 0.2 -> 11.4
G16: =G15 + 0.2 -> -18.4 | I16: =I15 + 0.2 -> -8.4 | K16: =K15 + 0.2 -> 1.6 | M16: =M15 + 0.2 -> 11.6 | P16: =P15 + 0.2 -> -18.4 | R16: =R15 + 0.2 -> -8.4 | T16: =T15 + 0.2 -> 1.6 | V16: =V15 + 0.2 -> 11.6
G17: =G16 + 0.2 -> -18.2 | I17: =I16 + 0.2 -> -8.2 | K17: =K16 + 0.2 -> 1.8 | M17: =M16 + 0.2 -> 11.8 | P17: =P16 + 0.2 -> -18.2 | R17: =R16 + 0.2 -> -8.2 | T17: =T16 + 0.2 -> 1.8 | V17: =V16 + 0.2 -> 11.8
G18: =G17 + 0.2 -> -18 | I18: =I17 + 0.2 -> -8 | K18: =K17 + 0.2 -> 2 | M18: =M17 + 0.2 -> 12 | P18: =P17 + 0.2 -> -18 | R18: =R17 + 0.2 -> -8 | T18: =T17 + 0.2 -> 2 | V18: =V17 + 0.2 -> 12
G19: =G18 + 0.2 -> -17.8 | I19: =I18 + 0.2 -> -7.8 | K19: =K18 + 0.2 -> 2.2 | M19: =M18 + 0.2 -> 12.2 | P19: =P18 + 0.2 -> -17.8 | R19: =R18 + 0.2 -> -7.8 | T19: =T18 + 0.2 -> 2.2 | V19: =V18 + 0.2 -> 12.2
G20: =G19 + 0.2 -> -17.6 | I20: =I19 + 0.2 -> -7.6 | K20: =K19 + 0.2 -> 2.4 | M20: =M19 + 0.2 -> 12.4 | P20: =P19 + 0.2 -> -17.6 | R20: =R19 + 0.2 -> -7.6 | T20: =T19 + 0.2 -> 2.4 | V20: =V19 + 0.2 -> 12.4
... G57: =G56 + 0.2 -> -10.2 | I57: =I56 + 0.2 -> -0.2 | K57: =K56 + 0.2 -> 9.8 | M57: =M56 + 0.2 -> 19.8 | P57: =P56 + 0.2 -> -10.2 | R57: =R56 + 0.2 -> -0.2 | T57: =T56 + 0.2 -> 9.8 | V57: =V56 + 0.2 -> 19.8
M58: =M57 + 0.2 -> 20 | V58: =V57 + 0.2 -> 20
G72: B：尋找X1、Xr | P72: B：尋找X1、Xr
H73: 第一亮紋 | I73: 第二亮紋 | J73: 第三亮紋 | K73: 第四亮紋 | L73: 第五亮紋 | M73: 第一暗紋 | Q73: 第一亮紋 | R73: 第二亮紋 | S73: 第三亮紋 | T73: 第四亮紋 | U73: 第五亮紋 | V73: 第一暗紋
G74: Xl (mm) | H74: 1 | I74: 2 | J74: 3 | K74: 4 | L74: 5 | M74: 6 | P74: Xl (mm)
G75: Xr (mm) | H75: 1 | I75: 2 | J75: 3 | K75: 4 | L75: 5 | M75: 6 | P75: Xr (mm)
G76: Θ | H76: =ABS((H74-H75)/2/G6) -> 0 | I76: =ABS((I74-I75)/2/G6) -> 0 | J76: =ABS((J74-J75)/2/G6) -> 0 | K76: =ABS((K74-K75)/2/G6) -> 0 | L76: =ABS((L74-L75)/2/G6) -> 0 | M76: =ABS((M74-M75)/2/G6) -> 0 | P76: Θ | Q76: =ABS((Q74-Q75)/2/P6) -> 0 | R76: =ABS((R74-R75)/2/P6) -> 0 | S76: =ABS((S74-S75)/2/P6) -> 0 | T76: =ABS((T74-T75)/2/P6) -> 0 | U76: =ABS((U74-U75)/2/P6) -> 0 | V76: =ABS((V74-V75)/2/P6) -> 0
G78: B：尋找X1、Xr(理論值) | P78: B：尋找X1、Xr(理論值)
H79: 第一亮紋 | I79: 第二亮紋 | J79: 第三亮紋 | K79: 第四亮紋 | L79: 第五亮紋 | M79: 第一暗紋 | Q79: 第一亮紋 | R79: 第二亮紋 | S79: 第三亮紋 | T79: 第四亮紋 | U79: 第五亮紋 | V79: 第一暗紋
G80: Xl (mm) | H80: =G6*M6/K6*-1 -> #DIV/0! | I80: =G6*M6*2/K6*-1 -> #DIV/0! | J80: =G6*M6*3/K6*-1 -> #DIV/0! | K80: =G6*M6*4/K6*-1 -> #DIV/0! | L80: =G6*M6*5/K6*-1 -> #DIV/0! | M80: =G6*M6/I6*-1 -> #DIV/0! | P80: Xl (mm) | Q80: =P6*V6/T6*-1 -> #DIV/0! | R80: =P6*V6*2/T6*-1 -> #DIV/0! | S80: =P6*V6*3/T6*-1 -> #DIV/0! | T80: =P6*V6*4/T6*-1 -> #DIV/0! | U80: =P6*V6*5/T6*-1 -> #DIV/0! | V80: =P6*V6/R6*-1 -> #DIV/0!
G81: Xr (mm) | H81: =G6*M6/K6 -> #DIV/0! | I81: =G6*M6*2/K6 -> #DIV/0! | J81: =G6*M6*3/K6 -> #DIV/0! | K81: =G6*M6*4/K6 -> #DIV/0! | L81: =G6*M6*5/K6 -> #DIV/0! | M81: =G6*M6/I6 -> #DIV/0! | P81: Xr (mm) | Q81: =P6*V6/T6 -> #DIV/0! | R81: =P6*V6*2/T6 -> #DIV/0! | S81: =P6*V6*3/T6*-1 -> #DIV/0! | T81: =P6*V6*4/T6 -> #DIV/0! | U81: =P6*V6*5/T6 -> #DIV/0! | V81: =P6*V6/R6 -> #DIV/0!
G82: Θ | H82: =ABS((H80-H81)/2/G6) -> #DIV/0! | I82: =ABS((I80-I81)/2/G6) -> #DIV/0! | J82: =ABS((J80-J81)/2/G6) -> #DIV/0! | K82: =ABS((K80-K81)/2/G6) -> #DIV/0! | L82: =ABS((L80-L81)/2/G6) -> #DIV/0! | M82: =ABS((M80-M81)/2/G6) -> #DIV/0! | P82: Θ | Q82: =ABS((Q80-Q81)/2/P6) -> #DIV/0! | R82: =ABS((R80-R81)/2/P6) -> #DIV/0! | S82: =ABS((S80-S81)/2/P6) -> #DIV/0! | T82: =ABS((T80-T81)/2/P6) -> #DIV/0! | U82: =ABS((U80-U81)/2/P6) -> #DIV/0! | V82: =ABS((V80-V81)/2/P6) -> #DIV/0!
G84: C：計算出單狹縫寬度a及雙狹縫距離d之值 | P84: C：計算出單狹縫寬度a及雙狹縫距離d之值
J85: 理論值 | K85: 實驗值 | L85: 百分誤差 (%) | S85: 理論值 | T85: 實驗值 | U85: 百分誤差 (%)
G86: 單狹縫寬度a (mm) | I86: Xl | J86: =I6 | K86: =ABS($G6*$M6/M74) -> 0.052916667 | L86: =ABS((K86-$J86)/$J86*100) -> #DIV/0! | P86: 單狹縫寬度a (mm) | R86: Xl | S86: =R6 | T86: =ABS($G6*$M6/V74) -> #DIV/0! | U86: =ABS((T86-$J86)/$J86*100) -> #DIV/0!
I87: Xr | K87: =ABS(G6*M6/M75) -> 0.052916667 | L87: =ABS((K87-J86)/J86*100) -> #DIV/0! | R87: Xr | T87: =ABS(P6*V6/V75) -> #DIV/0! | U87: =ABS((T87-S86)/S86*100) -> #DIV/0!
I88: 平均 | K88: =AVERAGE(K86:K87) -> 0.052916667 | L88: =ABS((K88-J86)/J86*100) -> #DIV/0! | R88: 平均 | T88: =AVERAGE(T86:T87) -> #DIV/0! | U88: =ABS((T88-S86)/S86*100) -> #DIV/0!
G89: 雙狹縫距離d (mm) | I89: Xl | J89: =K6 | K89: ='計算用'!I4 -> 0.3175 | L89: =ABS((K89-J89)/J89*100) -> #DIV/0! | P89: 雙狹縫距離d (mm) | R89: Xl | S89: =T6 | T89: ='計算用'!S4 -> #DIV/0! | U89: =ABS((T89-S89)/S89*100) -> #DIV/0!
I90: Xr | K90: ='計算用'!I6 -> 0.3175 | L90: =ABS((K90-J89)/J89*100) -> #DIV/0! | R90: Xr | T90: ='計算用'!S6 -> #DIV/0! | U90: =ABS((T90-S89)/S89*100) -> #DIV/0!
I91: 平均 | K91: ='計算用'!J4 -> 0.3175 | L91: =ABS((K91-J89)/J89*100) -> #DIV/0! | R91: 平均 | T91: ='計算用'!T4 -> #DIV/0! | U91: =ABS((T91-S89)/S89*100) -> #DIV/0!
G93: D：計算亮紋強度的比例 | P93: D：計算亮紋強度的比例
H94: 中央亮線 | I94: 第一亮線(左) | J94: 第一亮線 (右) | K94: 第二亮線 (左) | L94: 第二亮線 (右) | Q94: 中央亮線 | R94: 第一亮線 (左) | S94: 第一亮線 (右) | T94: 第二亮線 (左) | U94: 第二亮線 (右)
...

Sheet 計算用
B1: 第一次實驗 | L1: 第二次實驗
E2: 實驗值 | O2: 實驗值
B3: 理論值 | D3: ='實驗數據'!K6 | E3: 第一亮紋 | F3: 第二亮紋 | G3: 第四亮紋 | H3: 第五亮紋 | I3: 平均值 | J3: 平均值 | L3: 理論值 | N3: ='實驗數據'!U6 | O3: 第一亮紋 | P3: 第二亮紋 | Q3: 第四亮紋 | R3: 第五亮紋 | S3: 平均值 | T3: 平均值
B4: 雙狹縫距離d (mm) | D4: Xl | E4: =ABS('實驗數據'!$G6*'實驗數據'!$M6/'實驗數據'!H74) -> 0.3175 | F4: =ABS('實驗數據'!$G6*'實驗數據'!$M6*2/'實驗數據'!I74) -> 0.3175 | G4: =ABS('實驗數據'!$G6*'實驗數據'!$M6*4/'實驗數據'!K74) -> 0.3175 | H4: =ABS('實驗數據'!$G6*'實驗數據'!$M6*5/'實驗數據'!L74) -> 0.3175 | I4: =AVERAGE(E4:H4) -> 0.3175 | J4: =AVERAGE(I4,I6) -> 0.3175 | L4: 雙狹縫距離d (mm) | N4: Xl | O4: =ABS('實驗數據'!$G6*'實驗數據'!$M6/'實驗數據'!R74) -> #DIV/0! | P4: =ABS('實驗數據'!$G6*'實驗數據'!$M6*2/'實驗數據'!T74) -> #DIV/0! | Q4: =ABS('實驗數據'!$G6*'實驗數據'!$M6*4/'實驗數據'!U74) -> #DIV/0! | R4: =ABS('實驗數據'!$G6*'實驗數據'!$M6*5/'實驗數據'!V74) -> #DIV/0! | S4: =AVERAGE(O4:R4) -> #DIV/0! | T4: =AVERAGE(S4,S6) -> #DIV/0!
D5: 誤差(%) | E5: =ABS((E4-$D3)/$D3*100) -> #DIV/0! | F5: =ABS((F4-$D3)/$D3*100) -> #DIV/0! | G5: =ABS((G4-$D3)/$D3*100) -> #DIV/0! | H5: =ABS((H4-$D3)/$D3*100) -> #DIV/0! | I5: =ABS((I4-$D3)/$D3*100) -> #DIV/0! | N5: 誤差(%) | O5: =ABS((O4-$D3)/$D3*100) -> #DIV/0! | P5: =ABS((P4-$D3)/$D3*100) -> #DIV/0! | Q5: =ABS((Q4-$D3)/$D3*100) -> #DIV/0! | R5: =ABS((R4-$D3)/$D3*100) -> #DIV/0! | S5: =ABS((S4-$D3)/$D3*100) -> #DIV/0!
D6: Xr | E6: =ABS('實驗數據'!$G6*'實驗數據'!$M6/'實驗數據'!H75) -> 0.3175 | F6: =ABS('實驗數據'!$G6*'實驗數據'!$M6*2/'實驗數據'!I75) -> 0.3175 | G6: =ABS('實驗數據'!$G6*'實驗數據'!$M6*4/'實驗數據'!K75) -> 0.3175 | H6: =ABS('實驗數據'!$G6*'實驗數據'!$M6*5/'實驗數據'!L75) -> 0.3175 | I6: =AVERAGE(E6:H6) -> 0.3175 | N6: Xr | O6: =ABS('實驗數據'!$G6*'實驗數據'!$M6/'實驗數據'!R75) -> #DIV/0! | P6: =ABS('實驗數據'!$G6*'實驗數據'!$M6*2/'實驗數據'!T75) -> #DIV/0! | Q6: =ABS('實驗數據'!$G6*'實驗數據'!$M6*4/'實驗數據'!U75) -> #DIV/0! | R6: =ABS('實驗數據'!$G6*'實驗數據'!$M6*5/'實驗數據'!V75) -> #DIV/0! | S6: =AVERAGE(O6:R6) -> #DIV/0!
D7: 誤差(%) | E7: =ABS((E6-$D3)/$D3*100) -> #DIV/0! | F7: =ABS((F6-$D3)/$D3*100) -> #DIV/0! | G7: =ABS((G6-$D3)/$D3*100) -> #DIV/0! | H7: =ABS((H6-$D3)/$D3*100) -> #DIV/0! | I7: =ABS((I6-$D3)/$D3*100) -> #DIV/0! | J7: =ABS((J4-$D3)/$D3*100) -> #DIV/0! | N7: 誤差(%) | O7: =ABS((O6-$D3)/$D3*100) -> #DIV/0! | P7: =ABS((P6-$D3)/$D3*100) -> #DIV/0! | Q7: =ABS((Q6-$D3)/$D3*100) -> #DIV/0! | R7: =ABS((R6-$D3)/$D3*100) -> #DIV/0! | S7: =ABS((S6-$D3)/$D3*100) -> #DIV/0! | T7: =ABS((T4-$D3)/$D3*100) -> #DIV/0!
